Workbook

Sheet WBS
A1: Code | B1: Task Name | C1: Specification - what to do | D1: Category | E1: Owner (lead) | F1: Support | G1: Typology | H1: Priority | I1: Stage | J1: Predecessors | K1: Effort (person-days) | L1: Start | M1: Finish | N1: Span (cal. days) | O1: Day # from start | P1: Notes / watch-outs | S1: PROJECT START (edit to re-baseline)
A2: PF-01 | B2: Close open questions | C2: Get written answers from the organisers: (1) motor/driver/encoder quantities per team, (2) servo intent - brake, leg or other, (3) 1N5819 intent - power-ORing or flyback, (4) is frame material supplied or do we source it, (5) laser/waterjet/lathe access, (6) is the 150 mm cube dimension locked or free, (7) bench PSU availability. | D2: Formulation & Docs | E2: Dejan | F2: Pablo | G2: Management | H2: P0 | I2: S0 | K2: 0.5 | L2: 46226 | M2: 46226 | N2: =IF(L2="","",M2-L2+1) -> 1 | O2: =IF(L2="","",L2-$S$2+1) -> 1 | P2: Highest-leverage task in the plan - it is what unblocks the MF-01 order | S2: 46226
A3: PF-02 | B3: Problem statement & narrative | C3: Write the problem statement and lock the ADCS application framing: momentum-exchange actuation, reaction wheels as the standard spacecraft attitude actuator, Hayabusa2 MINERVA-II / MASCOT hopping as the low-gravity mobility precedent. One paragraph that every other section refers back to. | D3: Formulation & Docs | E3: Dejan | G3: Management | H3: P0 | I3: S0 | K3: 0.5 | L3: 46226 | M3: 46226 | N3: =IF(L3="","",M3-L3+1) -> 1 | O3: =IF(L3="","",L3-$S$2+1) -> 1 | S3: PROJECT END
A4: PF-03 | B4: Scope & requirements | C4: Define what is in and out of scope. Build the requirements table split into Functional (F), Performance (P) and Design constraint (D), each with an ID, a statement and a verification method. | D4: Formulation & Docs | E4: Dejan | F4: Pablo | G4: Analysis | H4: P0 | I4: S0 | J4: PF-02 | K4: 1 | L4: 46227 | M4: 46227 | N4: =IF(L4="","",M4-L4+1) -> 1 | O4: =IF(L4="","",L4-$S$2+1) -> 2 | S4: 46253
A5: PF-04 | B5: Milestones & staging | C5: Define the three prototype stages (S1 1-DoF rig, S2 3D cube, S3 jump) and write a quantitative, binary acceptance criterion for each gate - e.g. 'balances >=60 s and recovers from a finger poke', not 'works well'. | D5: Formulation & Docs | E5: Dejan | G5: Management | H5: P0 | I5: S0 | J5: PF-03 | K5: 0.5 | L5: 46228 | M5: 46228 | N5: =IF(L5="","",M5-L5+1) -> 1 | O5: =IF(L5="","",L5-$S$2+1) -> 3 | S5: Total effort (person-days)
A6: PF-05 | B6: Roles & RACI | C6: Assign a named owner per workstream (control, CAD, manufacturing, documentation) and per TDD section. Produce a one-page RACI so nobody is waiting on an unassigned task. | D6: Formulation & Docs | E6: Dejan | G6: Management | H6: P0 | I6: S0 | K6: 0.25 | L6: 46226 | M6: 46226 | N6: =IF(L6="","",M6-L6+1) -> 1 | O6: =IF(L6="","",L6-$S$2+1) -> 1 | S6: =SUM(K2:K95) -> 95
A7: PF-06 | B7: EoM - 1-DoF pendulum | C7: Derive the equations of motion of the reaction-wheel inverted pendulum by the Lagrangian method. Four states: body angle, body rate, wheel angle, wheel rate. Input = motor torque. Include viscous friction terms. | D7: Formulation & Docs | E7: Dejan | F7: Andrea | G7: Analysis | H7: P0 | I7: S1 | K7: 1 | L7: 46227 | M7: 46228 | N7: =IF(L7="","",M7-L7+1) -> 2 | O7: =IF(L7="","",L7-$S$2+1) -> 2 | S7: P0 effort (person-days)
A8: PF-07 | B8: EoM - 3D cube | C8: Derive the 3D equations of motion for the cube with three orthogonal wheels, for both the edge pivot and the corner pivot. Define body and inertial frames, the attitude parameterisation, and the coupled wheel/body angular momentum terms. | D8: Formulation & Docs | E8: Dejan | F8: Andrea | G8: Analysis | H8: P0 | I8: S2 | J8: PF-06 | K8: 2 | L8: 46230 | M8: 46231 | N8: =IF(L8="","",M8-L8+1) -> 2 | O8: =IF(L8="","",L8-$S$2+1) -> 5 | S8: =SUMIF(H2:H95,"P0",K2:K95) -> 69
A9: PF-08 | B9: Linearisation & controllability | C9: Identify the equilibria (edge and corner), linearise about each, and check controllability and observability of the resulting linear systems. Confirm the corner case is fully unstable with coupled axes. | D9: Formulation & Docs | E9: Dejan | F9: Andrea | G9: Analysis | H9: P0 | I9: S2 | J9: PF-07 | K9: 1 | L9: 46232 | M9: 46232 | N9: =IF(L9="","",M9-L9+1) -> 1 | O9: =IF(L9="","",L9-$S$2+1) -> 7 | S9: Task count (excl. milestones)
A10: PF-09 | B10: Mass / inertia / CoM budget | C10: Build the mass, inertia and centre-of-mass budget parametrically (symbols, not numbers) so the model stands up before hardware exists. Replace with CAD values at CD-18 and measured values at PF-16. | D10: Formulation & Docs | E10: Dejan | F10: Neisa | G10: Analysis | H10: P0 | I10: S0 | J10: PF-01 | K10: 0.75 | L10: 46228 | M10: 46228 | N10: =IF(L10="","",M10-L10+1) -> 1 | O10: =IF(L10="","",L10-$S$2+1) -> 3 | S10: =COUNTIF(D2:D95,"<>Milestone") -> 84
A11: PF-10 | B11: Jump-up analysis | C11: Energy method for the face-to-edge and edge-to-corner tips: CoM rise, inertia about the contact edge, required body rate, required stored angular momentum under an inelastic-collision model, and hence the minimum wheel inertia. Derive the brake impulse requirement dH/dt. | D11: Formulation & Docs | E11: Dejan | F11: Andrea | G11: Analysis | H11: P0 | I11: S3 | J11: PF-07;PF-09 | K11: 1 | L11: 46233 | M11: 46233 | N11: =IF(L11="","",M11-L11+1) -> 1 | O11: =IF(L11="","",L11-$S$2+1) -> 8 | P11: This is what sizes the wheel - it must be done before CD-02 is frozen
A12: PF-11a | B12: TDD - draft body | C12: EVERY MEMBER WRITES THEIR OWN SECTION, Dejan integrates. Section owners: Introduction, background and ADCS application narrative = Dejan. Project organisation, roles and timeline = Dejan. Scope, use cases and requirements table = Dejan with all leads reviewing. Mathematical modelling = Dejan + Andrea. Control architecture = Nicc + Andrea. Mechanical design intent = Neisa + Suvanna. Electrical design intent, architecture diagram and power budget = Pablo. Testing and validation plan = Nicc. Literature = Suvanna. Placeholder figures are acceptable at this point. | D12: Formulation & Docs | E12: ALL | F12: Dejan integrates - see spec for section owners | G12: Management | H12: P0 | I12: S0 | J12: PF-02;PF-03;PF-04;PF-05;PF-06;PF-09 | K12: 1.5 | L12: 46228 | M12: 46229 | N12: =IF(L12="","",M12-L12+1) -> 2 | O12: =IF(L12="","",L12-$S$2+1) -> 3 | P12: Anti-Parkinson checkpoint: due 26 Jul regardless of the 3 Aug deadline | S12: Yellow cells are inputs. Blank Start/Finish = deliberately unscheduled stretch task (CT-24, CT-25).
A13: PF-11b | B13: TDD - deepen + S1 data | C13: Upgrade the technical sections: full 3D equations of motion, linearisation and controllability argument, jump-up momentum budget, control architecture. Then insert the S1 hardware evidence - rig photos, balance trace, disturbance-recovery plot, and the measured Kt / J_wheel / friction from CT-11. | D13: Formulation & Docs | E13: ALL | F13: Dejan integrates | G13: Management | H13: P0 | I13: S0 | J13: PF-11a;PF-07;PF-08;PF-10;CT-10;CT-11 | K13: 1 | L13: 46235 | M13: 46236 | N13: =IF(L13="","",M13-L13+1) -> 2 | O13: =IF(L13="","",L13-$S$2+1) -> 10 | P13: Tight - consumes CT-10/CT-11 results almost same-day. Pull CT-10 left if you can
A14: PF-11c | B14: TDD - assemble & submit | C14: Final assembly: make every figure presentable, run a full read-through for internal consistency, tighten the application story, format references, submit. | D14: Formulation & Docs | E14: ALL | F14: Dejan integrates | G14: Management | H14: P0 | I14: S0 | J14: PF-11b | K14: 1 | L14: 46237 | M14: 46237 | N14: =IF(L14="","",M14-L14+1) -> 1 | O14: =IF(L14="","",L14-$S$2+1) -> 12 | P14: DELIVERABLE - Monday 3 August
A15: PF-12 | B15: Literature & references | C15: Collect and format the reference set: ETH Cubli (IROS 2012, ECC 2013), One-Wheel Cubli (Mechatronics 2023), CubeSat ADCS design guides, MINERVA-II / MASCOT mission reports, LQR and optimal-control texts. Pull the ETH PDFs for the modelling section. | D15: Formulation & Docs | E15: ALL | F15: Suvanna collates | G15: Management | H15: P1 | I15: S0 | K15: 0.5 | L15: 46228 | M15: 46228 | N15: =IF(L15="","",M15-L15+1) -> 1 | O15: =IF(L15="","",L15-$S$2+1) -> 3
A16: PF-13 | B16: Risk register | C16: Tabulate the risks with trigger, impact, owner and mitigation. Minimum set: rim lead time, rotor unbalance, printed-bracket compliance, 5 V rail brownout, yaw drift, wrong motor quantity. | D16: Formulation & Docs | E16: ALL | F16: Pablo collates | G16: Management | H16: P1 | I16: S0 | J16: PF-04 | K16: 0.5 | L16: 46232 | M16: 46232 | N16: =IF(L16="","",M16-L16+1) -> 1 | O16: =IF(L16="","",L16-$S$2+1) -> 7
A17: PF-14 | B17: Test & validation plan | C17: Define how each milestone is verified and which numbers get reported: pointing accuracy, slew settling time, jitter / pointing stability, disturbance-recovery time. These are the metrics a real ADCS is graded on - use them instead of 'it balances'. | D17: Formulation & Docs | E17: Dejan | F17: Andrea | G17: Analysis | H17: P1 | I17: S0 | J17: PF-04 | K17: 0.5 | L17: 46233 | M17: 46233 | N17: =IF(L17="","",M17-L17+1) -> 1 | O17: =IF(L17="","",L17-$S$2+1) -> 8
A18: PF-15 | B18: System-ID plan | C18: Specify the experiments that will produce the plant parameters: Kt by torque arm or known-inertia spin-up, J_wheel by J=tau/alpha, viscous friction by coast-down, loop latency by step-response timing. | D18: Formulation & Docs | E18: Dejan | F18: Nicc | G18: Analysis | H18: P1 | I18: S1 | J18: PF-06 | K18: 0.5 | L18: 46231 | M18: 46231 | N18: =IF(L18="","",M18-L18+1) -> 1 | O18: =IF(L18="","",L18-$S$2+1) -> 6
A19: PF-16 | B19: Model update - real params | C19: Substitute the measured parameters from CT-11 and the CAD mass properties from CD-18 into the model, then re-run the torque-authority and jump-up sizing calculations with real numbers. | D19: Formulation & Docs | E19: Dejan | F19: Andrea | G19: Analysis | H19: P0 | I19: S2 | J19: CT-11;CD-18 | K19: 0.5 | L19: 46237 | M19: 46238 | N19: =IF(L19="","",M19-L19+1) -> 2 | O19: =IF(L19="","",L19-$S$2+1) -> 12
A20: PF-17a | B20: Progress note #1 | C20: Short written status against the milestone gates, plus an incremental update to the TDD sections affected by that week's results. | D20: Formulation & Docs | E20: ALL | F20: Dejan integrates | G20: Management | H20: P1 | J20: PF-11c | K20: 0.25 | L20: 46243 | M20: 46243 | N20: =IF(L20="","",M20-L20+1) -> 1 | O20: =IF(L20="","",L20-$S$2+1) -> 18
A21: PF-17b | B21: Progress note #2 | C21: Same as PF-17a for the following week. | D21: Formulation & Docs | E21: ALL | F21: Dejan integrates | G21: Management | H21: P1 | J21: PF-17a | K21: 0.25 | L21: 46250 | M21: 46250 | N21: =IF(L21="","",M21-L21+1) -> 1 | O21: =IF(L21="","",L21-$S$2+1) -> 25
A22: PF-18 | B22: Final report (TDD v2) | C22: Extend the TDD into the final deliverable: experimental results and plots for every stage reached, the ADCS metrics table, lessons learned, and an explicit honest statement of what was achieved versus what was scoped. | D22: Formulation & Docs | E22: ALL | F22: Dejan integrates | G22: Management | H22: P0 | J22: CT-19;CT-20;CT-21 | K22: 2.5 | L22: 46249 | M22: 46253 | N22: =IF(L22="","",M22-L22+1) -> 5 | O22: =IF(L22="","",L22-$S$2+1) -> 24 | P22: FINAL DELIVERABLE
A23: PF-19 | B23: Demo video & deck | C23: Film the demonstrations including 240 fps slow-motion of the jump-up, cut a short video, and build the presentation deck around the stabilise > reorient > propel > traverse capability ladder. | D23: Formulation & Docs | E23: ALL | F23: Suvanna edits | G23: Management | H23: P0 | J23: CT-19;CT-21 | K23: 1 | L23: 46251 | M23: 46253 | N23: =IF(L23="","",M23-L23+1) -> 3 | O23: =IF(L23="","",L23-$S$2+1) -> 26
A24: CT-01 | B24: Sim environment + 1-DoF plant | C24: Set up the simulation environment (Python + CasADi, or MATLAB). Implement the PF-06 plant and validate it: with zero input and zero friction, total energy must be conserved. | D24: Control & Software | E24: Andrea | G24: Software | H24: P0 | I24: S1 | J24: PF-06 | K24: 1 | L24: 46226 | M24: 46227 | N24: =IF(L24="","",M24-L24+1) -> 2 | O24: =IF(L24="","",L24-$S$2+1) -> 1
A25: CT-02 | B25: LQR 1-DoF (sim) | C25: Design and tune an LQR about the upright equilibrium in simulation. Sweep robustness against J_wheel error, added loop delay and torque saturation so the gains survive contact with real hardware. | D25: Control & Software | E25: Andrea | F25: Dejan | G25: Software | H25: P0 | I25: S1 | J25: CT-01;PF-08 | K25: 1 | L25: 46229 | M25: 46230 | N25: =IF(L25="","",M25-L25+1) -> 2 | O25: =IF(L25="","",L25-$S$2+1) -> 4
A26: CT-03 | B26: Complementary filter | C26: Implement tilt estimation v1: gravity vector from the accelerometer for low-frequency tilt, gyro integration for high-frequency rate, blended by a complementary filter. Tune the crossover in simulation with injected noise and bias. | D26: Control & Software | E26: Nicc | G26: Software | H26: P0 | I26: S1 | J26: CT-01 | K26: 1 | L26: 46230 | M26: 46231 | N26: =IF(L26="","",M26-L26+1) -> 2 | O26: =IF(L26="","",L26-$S$2+1) -> 5
A27: CT-04 | B27: Firmware architecture | C27: Decide and document the firmware structure: inner/outer loop rates (the 500 vs 1000 Hz decision driven by the BMI270 I2C read cost), task scheduling, state-machine skeleton, logging hooks, and where safety logic lives. | D27: Control & Software | E27: Nicc | F27: Andrea | G27: Software | H27: P0 | I27: S1 | K27: 1 | L27: 46227 | M27: 46228 | N27: =IF(L27="","",M27-L27+1) -> 2 | O27: =IF(L27="","",L27-$S$2+1) -> 2 | P27: The IMU interface decision constrains the whole firmware - make it in week 1
A28: CT-05 | B28: CAN-FD comms layer | C28: Write the Teensy-to-moteus communication layer: transmit torque commands, parse the reply frame for wheel position, velocity, current and temperature. The reply frame IS the wheel-state feedback - no separate wiring. | D28: Control & Software | E28: Nicc | F28: Pablo | G28: Software | H28: P0 | I28: S1 | J28: CT-04;MF-03 | K28: 1.5 | L28: 46230 | M28: 46231 | N28: =IF(L28="","",M28-L28+1) -> 2 | O28: =IF(L28="","",L28-$S$2+1) -> 5
A29: CT-06 | B29: BMI270 driver | C29: Write the IMU driver and resolve the interface question: check whether the breakout exposes SPI pads; if not, use the FIFO plus a data-ready interrupt, or drop the outer loop to 500 Hz. A blocking 400 kHz I2C read costs ~300 us. | D29: Control & Software | E29: Nicc | G29: Software | H29: P0 | I29: S1 | J29: CT-04 | K29: 1 | L29: 46231 | M29: 46232 | N29: =IF(L29="","",M29-L29+1) -> 2 | O29: =IF(L29="","",L29-$S$2+1) -> 6
A30: CT-07 | B30: IMU cal + lever arm | C30: Calibrate gyro bias and accelerometer scale, record the mounting rotation matrix, and implement the lever-arm correction a_meas = g_body + w x (w x r) + alpha x r. The cube rotates about the contact corner, not about the IMU. | D30: Control & Software | E30: Nicc | F30: Andrea | G30: Software | H30: P0 | I30: S1 | J30: CT-06 | K30: 1 | L30: 46232 | M30: 46233 | N30: =IF(L30="","",M30-L30+1) -> 2 | O30: =IF(L30="","",L30-$S$2+1) -> 7 | P30: Skip the lever arm and your tilt estimate is corrupted exactly during fast recovery
A31: CT-08 | B31: Telemetry link | C31: Define the Teensy-to-ESP32 UART protocol, stream state over Wi-Fi, and build a ground-station live plot plus command path for start/stop and gain changes. Treat the link as strictly non-safety-critical. | D31: Control & Software | E31: Nicc | G31: Software | H31: P1 | I31: S1 | J31: CT-04 | K31: 1.5 | L31: 46233 | M31: 46235 | N31: =IF(L31="","",M31-L31+1) -> 3 | O31: =IF(L31="","",L31-$S$2+1) -> 8 | P31: Pays for itself: tune LQR gains in an afternoon instead of a week
A32: CT-09 | B32: Safety layer | C32: Implement the software safety envelope: enable the moteus watchdog, tilt-limit auto-disarm, wheel-speed cap, explicit arm/disarm command, and latching fault states that require a deliberate reset. | D32: Control & Software | E32: Nicc | F32: Andrea | G32: Software | H32: P0 | I32: S1 | J32: CT-05 | K32: 1 | L32: 46233 | M32: 46234 | N32: =IF(L32="","",M32-L32+1) -> 2 | O32: =IF(L32="","",L32-$S$2+1) -> 8
A33: CT-10 | B33: S1 - balance 1-DoF rig | C33: Bring the full chain up on the rig: IMU > Teensy > CAN-FD > moteus > wheel. Port the LQR and estimator to hardware, then tune gains against live telemetry until the pendulum balances and rejects disturbance. | D33: Control & Software | E33: Nicc | F33: Andrea | G33: Verification | H33: P0 | I33: S1 | J33: CT-02;CT-03;CT-07;CT-09;MF-08 | K33: 2 | L33: 46234 | M33: 46236 | N33: =IF(L33="","",M33-L33+1) -> 3 | O33: =IF(L33="","",L33-$S$2+1) -> 9 | P33: STAGE S1 GATE - protect this task at all costs
A34: CT-11 | B34: System ID on rig | C34: Execute the PF-15 experiments on the rig: measure real Kt, wheel inertia by spin-up, viscous friction by coast-down, and end-to-end loop latency. Produce a parameter table that replaces every symbolic value. | D34: Control & Software | E34: Andrea | F34: Nicc | G34: Verification | H34: P0 | I34: S1 | J34: MF-08 | K34: 1 | L34: 46235 | M34: 46236 | N34: =IF(L34="","",M34-L34+1) -> 2 | O34: =IF(L34="","",L34-$S$2+1) -> 10
A35: CT-12 | B35: 3D plant model (sim) | C35: Implement the PF-07 3D model in simulation for both edge and corner pivots, and validate it against the analytical derivation and against conserved quantities. | D35: Control & Software | E35: Andrea | F35: Dejan | G35: Software | H35: P0 | I35: S2 | J35: PF-07;CT-01 | K35: 2 | L35: 46237 | M35: 46238 | N35: =IF(L35="","",M35-L35+1) -> 2 | O35: =IF(L35="","",L35-$S$2+1) -> 12
A36: CT-13 | B36: LQR edge (sim) | C36: Design and tune the LQR for edge balance in simulation, using the CD-18 inertia tensor. Verify torque authority against the recoverable-tilt calculation. | D36: Control & Software | E36: Andrea | G36: Software | H36: P0 | I36: S2 | J36: CT-12;PF-08 | K36: 1 | L36: 46239 | M36: 46239 | N36: =IF(L36="","",M36-L36+1) -> 1 | O36: =IF(L36="","",L36-$S$2+1) -> 14
A37: CT-14 | B37: LQR corner (sim) | C37: Design the fully coupled three-axis LQR for corner balance in simulation. This is the hardest equilibrium - all axes coupled, fully unstable. | D37: Control & Software | E37: Andrea | F37: Dejan | G37: Software | H37: P0 | I37: S2 | J37: CT-13 | K37: 1.5 | L37: 46239 | M37: 46240 | N37: =IF(L37="","",M37-L37+1) -> 2 | O37: =IF(L37="","",L37-$S$2+1) -> 14
A38: CT-15 | B38: EKF / MEKF estimator | C38: Upgrade the estimator to a 3D EKF or multiplicative EKF with gyro bias states. Characterise and document the yaw-drift behaviour: with no magnetometer, absolute heading is unobservable. | D38: Control & Software | E38: Nicc | F38: Andrea | G38: Software | H38: P1 | I38: S2 | J38: CT-07;CT-12 | K38: 2 | L38: 46240 | M38: 46242 | N38: =IF(L38="","",M38-L38+1) -> 3 | O38: =IF(L38="","",L38-$S$2+1) -> 15 | P38: Yaw unobservability is the hook that ties this project to the star-tracker team
A39: CT-16 | B39: Momentum management | C39: Add the outer wheel-speed regulation loop that bleeds stored momentum back toward zero so the wheels do not saturate during long holds. This is the direct analogue of spacecraft momentum desaturation. | D39: Control & Software | E39: Andrea | G39: Software | H39: P1 | I39: S2 | J39: CT-14 | K39: 1 | L39: 46244 | M39: 46244 | N39: =IF(L39="","",M39-L39+1) -> 1 | O39: =IF(L39="","",L39-$S$2+1) -> 19 | P39: The strongest single ADCS talking point in the project
A40: CT-17 | B40: Mode state machine | C40: Implement the mode logic and the guarded transitions between them: idle > arm > edge balance > corner balance > slew > wheel spin-up > jump > catch > safe, with a defined abort path from every state. | D40: Control & Software | E40: Nicc | G40: Software | H40: P0 | I40: S2 | J40: CT-09;CT-04 | K40: 1 | L40: 46241 | M40: 46241 | N40: =IF(L40="","",M40-L40+1) -> 1 | O40: =IF(L40="","",L40-$S$2+1) -> 16
...

Sheet Legend & Assumptions
A1: CUBLI PROJECT - WBS LEGEND & ASSUMPTIONS
A3: COLUMNS
A4: Code | B4: Unique task ID. Prefix = workstream. M-codes are zero-duration milestone gates.
A5: Task Name | B5: Short label - use this one as the Gantt bar label.
A6: Specification | B6: What actually has to be done. This is the working instruction for whoever owns the task.
A7: Effort (person-days) | B7: Work content for ONE person. Not the same as calendar span - parallel work is expected.
A8: Start / Finish | B8: Scheduled calendar dates. Blank = deliberately unscheduled stretch task.
A9: Span (cal. days) | B9: Formula = Finish - Start + 1.
A10: Day # from start | B10: Formula = Start - project start + 1. Use as the X offset for a stacked-bar Gantt.
A11: Predecessors | B11: Semicolon-separated codes that must complete first.
A12: Notes / watch-outs | B12: The failure mode or the reason the task exists. Read before starting the task.
A14: CATEGORY (workstream)
A15: Formulation & Docs | B15: Modelling, derivations, requirements, TDD and final report. Cross-cutting: one owner, everyone contributes.
A16: Control & Software | B16: Control law design, estimation, embedded firmware, telemetry, hardware bring-up tests.
A17: CAD Design | B17: All mechanical design: wheels, brackets, frame, tooling, brake linkage.
A18: Manufacturing & Circuits | B18: Procurement, 3D printing, fabrication, soldering, harnessing, assembly, integration tests.
A19: Milestone | B19: Zero-effort gate. Binary pass/fail, no partial credit.
A21: TYPOLOGY
A22: Analysis | B22: Derivation, calculation, budget.
A23: Design | B23: CAD or schematic design work.
A24: Build | B24: Physical fabrication, printing, assembly, soldering.
A25: Software | B25: Code written on a computer.
A26: Verification | B26: Test on hardware against a stated criterion.
A27: Management | B27: Planning and documentation.
A28: Procurement | B28: Buying or securing equipment.
A30: PRIORITY
A31: P0 | B31: Critical path. Slipping this slips the project end date.
A32: P1 | B32: Important, has float, but a milestone is degraded without it.
A33: P2 | B33: Stretch / nice-to-have. Cut first.
A35: STAGE (prototype)
A36: S0 | B36: Common foundation - applies to all prototypes.
A37: S1 | B37: 1-DoF reaction-wheel inverted pendulum (ETH-style single axis).
A38: S2 | B38: 3D Cubli - edge balance, corner balance, commanded slew.
A39: S3 | B39: Jump-up with the braking system.
A41: ASSUMPTIONS (change these and the schedule changes)
A42: Team size | B42: 4-6 people: one control lead, one CAD lead, one hardware lead, one documentation owner. ASSUMPTION - not confirmed.
A43: Working days | B43: All 7 days per week treated as working days. If weekends are off, ~8 working days are lost and stage S3 is not achievable.
A44: 3D printer | B44: ONE printer, ~40-60 h total, strictly serial. Queue order: jigs > S1 rig > precision encoder/magnet parts > cube structure > TPU protection.
A45: Actuation sets | B45: 3 motors + 3 moteus + 3 MA600 per cube, plus one spare set so the 1-DoF rig survives cube integration. UNCONFIRMED - BOM open question #1.
A46: Cube geometry | B46: 150 mm, ~2.0 kg. Source: cubli_hardware_architecture.md section 5, itself an assumption.
...

Sheet Resource Loading
A1: RESOURCE LOADING - lead-owned effort per person
A2: Counts only tasks where the person is the LEAD. Support effort is real but not counted here, so these are lower bounds. 28 calendar days available (23 Jul - 19 Aug).
A4: Person | B4: Role | C4: Lead tasks | D4: Lead effort | E4: Shared doc share | F4: TOTAL effort | G4: P0 lead effort | H4: Required availability | I4: Assessment
A5: Neisa | B5: CAD & 3D printing | C5: =COUNTIF(WBS!$E$2:$E$95,A5) -> 12 | D5: =SUMIF(WBS!$E$2:$E$95,A5,WBS!$K$2:$K$95) -> 13.25 | E5: =SUMIF(WBS!$E$2:$E$95,"ALL",WBS!$K$2:$K$95)/$B$15 -> 1.4166667 | F5: =D5+E5 -> 14.666667 | G5: =SUMIFS(WBS!$K$2:$K$95,WBS!$E$2:$E$95,A5,WBS!$H$2:$H$95,"P0") -> 12 | H5: =F5/$B$14 -> 0.52380952 | I5: =IF(H5>0.75,"OVERLOADED",IF(H5>0.5,"Heavy",IF(H5>0.3,"Balanced","Has float"))) -> Heavy
A6: Suvanna | B6: CAD & mechanical fab | C6: =COUNTIF(WBS!$E$2:$E$95,A6) -> 15 | D6: =SUMIF(WBS!$E$2:$E$95,A6,WBS!$K$2:$K$95) -> 16.25 | E6: =SUMIF(WBS!$E$2:$E$95,"ALL",WBS!$K$2:$K$95)/$B$15 -> 1.4166667 | F6: =D6+E6 -> 17.666667 | G6: =SUMIFS(WBS!$K$2:$K$95,WBS!$E$2:$E$95,A6,WBS!$H$2:$H$95,"P0") -> 10 | H6: =F6/$B$14 -> 0.63095238 | I6: =IF(H6>0.75,"OVERLOADED",IF(H6>0.5,"Heavy",IF(H6>0.3,"Balanced","Has float"))) -> Heavy
A7: Dejan | B7: Mathematics & formulation (doc owner) | C7: =COUNTIF(WBS!$E$2:$E$95,A7) -> 13 | D7: =SUMIF(WBS!$E$2:$E$95,A7,WBS!$K$2:$K$95) -> 10 | E7: =SUMIF(WBS!$E$2:$E$95,"ALL",WBS!$K$2:$K$95)/$B$15 -> 1.4166667 | F7: =D7+E7 -> 11.416667 | G7: =SUMIFS(WBS!$K$2:$K$95,WBS!$E$2:$E$95,A7,WBS!$H$2:$H$95,"P0") -> 9 | H7: =F7/$B$14 -> 0.4077381 | I7: =IF(H7>0.75,"OVERLOADED",IF(H7>0.5,"Heavy",IF(H7>0.3,"Balanced","Has float"))) -> Balanced
A8: Nicc | B8: Control - firmware & estimation | C8: =COUNTIF(WBS!$E$2:$E$95,A8) -> 12 | D8: =SUMIF(WBS!$E$2:$E$95,A8,WBS!$K$2:$K$95) -> 16 | E8: =SUMIF(WBS!$E$2:$E$95,"ALL",WBS!$K$2:$K$95)/$B$15 -> 1.4166667 | F8: =D8+E8 -> 17.416667 | G8: =SUMIFS(WBS!$K$2:$K$95,WBS!$E$2:$E$95,A8,WBS!$H$2:$H$95,"P0") -> 9.5 | H8: =F8/$B$14 -> 0.62202381 | I8: =IF(H8>0.75,"OVERLOADED",IF(H8>0.5,"Heavy",IF(H8>0.3,"Balanced","Has float"))) -> Heavy
A9: Andrea | B9: Control - control law & simulation | C9: =COUNTIF(WBS!$E$2:$E$95,A9) -> 13 | D9: =SUMIF(WBS!$E$2:$E$95,A9,WBS!$K$2:$K$95) -> 19 | E9: =SUMIF(WBS!$E$2:$E$95,"ALL",WBS!$K$2:$K$95)/$B$15 -> 1.4166667 | F9: =D9+E9 -> 20.416667 | G9: =SUMIFS(WBS!$K$2:$K$95,WBS!$E$2:$E$95,A9,WBS!$H$2:$H$95,"P0") -> 11.5 | H9: =F9/$B$14 -> 0.72916667 | I9: =IF(H9>0.75,"OVERLOADED",IF(H9>0.5,"Heavy",IF(H9>0.3,"Balanced","Has float"))) -> Heavy
A10: Pablo | B10: Circuits, layout & manufacturing | C10: =COUNTIF(WBS!$E$2:$E$95,A10) -> 10 | D10: =SUMIF(WBS!$E$2:$E$95,A10,WBS!$K$2:$K$95) -> 12 | E10: =SUMIF(WBS!$E$2:$E$95,"ALL",WBS!$K$2:$K$95)/$B$15 -> 1.4166667 | F10: =D10+E10 -> 13.416667 | G10: =SUMIFS(WBS!$K$2:$K$95,WBS!$E$2:$E$95,A10,WBS!$H$2:$H$95,"P0") -> 10 | H10: =F10/$B$14 -> 0.47916667 | I10: =IF(H10>0.75,"OVERLOADED",IF(H10>0.5,"Heavy",IF(H10>0.3,"Balanced","Has float"))) -> Balanced
A11: TOTAL | C11: =SUM(C5:C10) -> 75 | D11: =SUM(D5:D10) -> 86.5 | E11: =SUM(E5:E10) -> 8.5 | F11: =SUM(F5:F10) -> 95 | G11: =SUM(G5:G10) -> 62
A13: Calendar days available
B14: 28 | C14: <- edit these two cells
A15: Team size (shared doc divisor) | B15: 6
A16: HOW THE WORK WAS SPLIT
A17: Control (Nicc / Andrea) | B17: Split by function, not by turns. Nicc owns firmware, drivers, estimation and the safety layer; Andrea owns the plant models, LQR design and simulation. They pair on every hardware bring-up task (CT-10, CT-18, CT-19, CT-21) because those are the ones where a second pair of eyes on the telemetry is worth more than a second task being started.
A18: CAD (Neisa / Suvanna) | B18: Neisa owns structure and the parts that feed her own print queue (frame, brackets, trays, CAD freeze). Suvanna owns the precision and long-lead items: reaction wheel, magnet carrier, brake linkage, mass properties. Suvanna also absorbs the wheel fabrication and balancing, which is mechanical work that would otherwise land on Pablo.
A19: Manufacturing (Pablo) | B19: As originally scoped, manufacturing was 25 person-days for one person, on the critical path twice. All four print queues (MF-04, MF-05, MF-12, MF-14) have been reassigned to Neisa, and wheel fabrication, balancing, frame cutting and the brake build to Suvanna. Pablo keeps procurement, bench bring-up, schematic, perfboard, harness, integration and the smoke test - the electrical spine.
A20: Formulation (Dejan) | B20: Dejan is both the mathematician and the document owner, which is the second-heaviest single load in the project. Literature review and the demo video/deck moved to Suvanna, and the risk register to Pablo. The TDD assembly tasks (PF-11a/b/c) must be genuinely co-written - each workstream lead drafts their own section and Dejan integrates, otherwise he becomes the bottleneck in week 2.
A21: Warning | B21: These figures count LEAD effort only. Support time is real and unbudgeted, so treat every 'required availability' percentage as a floor, not a forecast.

Sheet GANTT
A1: CUBLI PROJECT GANTT - 23 July to 19 August 2026
A2: Bars are formula-driven from the WBS sheet: change a Start or Finish there and this chart updates. Colour = workstream. Diamonds = milestone gates.
G3: W1 | H3: W1 | I3: W1 | J3: W1 | K3: W1 | L3: W1 | M3: W1 | N3: W2 | O3: W2 | P3: W2 | Q3: W2 | R3: W2 | S3: W2 | T3: W2 | U3: W3 | V3: W3 | W3: W3 | X3: W3 | Y3: W3 | Z3: W3 | AA3: W3 | AB3: W4 | AC3: W4 | AD3: W4 | AE3: W4 | AF3: W4 | AG3: W4 | AH3: W4
A4: Code | B4: Task Name | C4: Owner | D4: Category | E4: Start | F4: Finish | G4: 46226 | H4: 46227 | I4: 46228 | J4: 46229 | K4: 46230 | L4: 46231 | M4: 46232 | N4: 46233 | O4: 46234 | P4: 46235 | Q4: 46236 | R4: 46237 | S4: 46238 | T4: 46239 | U4: 46240 | V4: 46241 | W4: 46242 | X4: 46243 | Y4: 46244 | Z4: 46245 | AA4: 46246 | AB4: 46247 | AC4: 46248 | AD4: 46249 | AE4: 46250 | AF4: 46251 | AG4: 46252 | AH4: 46253
A5: =WBS!A2 -> PF-01 | B5: =WBS!B2 -> Close open questions | C5: =WBS!E2 -> Dejan | D5: =WBS!D2 -> Formulation & Docs | E5: =WBS!L2 -> 46226 | F5: =WBS!M2 -> 46226 | G5: =IF($E5="","",IF(AND(G$4>=$E5,G$4<=$F5),IF($D5="Milestone","D",1),"")) -> 1 | H5: =IF($E5="","",IF(AND(H$4>=$E5,H$4<=$F5),IF($D5="Milestone","D",1),"")) | I5: =IF($E5="","",IF(AND(I$4>=$E5,I$4<=$F5),IF($D5="Milestone","D",1),"")) | J5: =IF($E5="","",IF(AND(J$4>=$E5,J$4<=$F5),IF($D5="Milestone","D",1),"")) | K5: =IF($E5="","",IF(AND(K$4>=$E5,K$4<=$F5),IF($D5="Milestone","D",1),"")) | L5: =IF($E5="","",IF(AND(L$4>=$E5,L$4<=$F5),IF($D5="Milestone","D",1),"")) | M5: =IF($E5="","",IF(AND(M$4>=$E5,M$4<=$F5),IF($D5="Milestone","D",1),"")) | N5: =IF($E5="","",IF(AND(N$4>=$E5,N$4<=$F5),IF($D5="Milestone","D",1),"")) | ... AH5: =IF($E5="","",IF(AND(AH$4>=$E5,AH$4<=$F5),IF($D5="Milestone","D",1),""))
A6: =WBS!A3 -> PF-02 | B6: =WBS!B3 -> Problem statement & narrative | C6: =WBS!E3 -> Dejan | D6: =WBS!D3 -> Formulation & Docs | E6: =WBS!L3 -> 46226 | F6: =WBS!M3 -> 46226 | G6: =IF($E6="","",IF(AND(G$4>=$E6,G$4<=$F6),IF($D6="Milestone","D",1),"")) -> 1 | H6: =IF($E6="","",IF(AND(H$4>=$E6,H$4<=$F6),IF($D6="Milestone","D",1),"")) | I6: =IF($E6="","",IF(AND(I$4>=$E6,I$4<=$F6),IF($D6="Milestone","D",1),"")) | J6: =IF($E6="","",IF(AND(J$4>=$E6,J$4<=$F6),IF($D6="Milestone","D",1),"")) | K6: =IF($E6="","",IF(AND(K$4>=$E6,K$4<=$F6),IF($D6="Milestone","D",1),"")) | L6: =IF($E6="","",IF(AND(L$4>=$E6,L$4<=$F6),IF($D6="Milestone","D",1),"")) | M6: =IF($E6="","",IF(AND(M$4>=$E6,M$4<=$F6),IF($D6="Milestone","D",1),"")) | N6: =IF($E6="","",IF(AND(N$4>=$E6,N$4<=$F6),IF($D6="Milestone","D",1),"")) | ... AH6: =IF($E6="","",IF(AND(AH$4>=$E6,AH$4<=$F6),IF($D6="Milestone","D",1),""))
A7: =WBS!A4 -> PF-03 | B7: =WBS!B4 -> Scope & requirements | C7: =WBS!E4 -> Dejan | D7: =WBS!D4 -> Formulation & Docs | E7: =WBS!L4 -> 46227 | F7: =WBS!M4 -> 46227 | G7: =IF($E7="","",IF(AND(G$4>=$E7,G$4<=$F7),IF($D7="Milestone","D",1),"")) | H7: =IF($E7="","",IF(AND(H$4>=$E7,H$4<=$F7),IF($D7="Milestone","D",1),"")) -> 1 | I7: =IF($E7="","",IF(AND(I$4>=$E7,I$4<=$F7),IF($D7="Milestone","D",1),"")) | J7: =IF($E7="","",IF(AND(J$4>=$E7,J$4<=$F7),IF($D7="Milestone","D",1),"")) | K7: =IF($E7="","",IF(AND(K$4>=$E7,K$4<=$F7),IF($D7="Milestone","D",1),"")) | L7: =IF($E7="","",IF(AND(L$4>=$E7,L$4<=$F7),IF($D7="Milestone","D",1),"")) | M7: =IF($E7="","",IF(AND(M$4>=$E7,M$4<=$F7),IF($D7="Milestone","D",1),"")) | N7: =IF($E7="","",IF(AND(N$4>=$E7,N$4<=$F7),IF($D7="Milestone","D",1),"")) | ... AH7: =IF($E7="","",IF(AND(AH$4>=$E7,AH$4<=$F7),IF($D7="Milestone","D",1),""))
A8: =WBS!A5 -> PF-04 | B8: =WBS!B5 -> Milestones & staging | C8: =WBS!E5 -> Dejan | D8: =WBS!D5 -> Formulation & Docs | E8: =WBS!L5 -> 46228 | F8: =WBS!M5 -> 46228 | G8: =IF($E8="","",IF(AND(G$4>=$E8,G$4<=$F8),IF($D8="Milestone","D",1),"")) | H8: =IF($E8="","",IF(AND(H$4>=$E8,H$4<=$F8),IF($D8="Milestone","D",1),"")) | I8: =IF($E8="","",IF(AND(I$4>=$E8,I$4<=$F8),IF($D8="Milestone","D",1),"")) -> 1 | J8: =IF($E8="","",IF(AND(J$4>=$E8,J$4<=$F8),IF($D8="Milestone","D",1),"")) | K8: =IF($E8="","",IF(AND(K$4>=$E8,K$4<=$F8),IF($D8="Milestone","D",1),"")) | L8: =IF($E8="","",IF(AND(L$4>=$E8,L$4<=$F8),IF($D8="Milestone","D",1),"")) | M8: =IF($E8="","",IF(AND(M$4>=$E8,M$4<=$F8),IF($D8="Milestone","D",1),"")) | N8: =IF($E8="","",IF(AND(N$4>=$E8,N$4<=$F8),IF($D8="Milestone","D",1),"")) | ... AH8: =IF($E8="","",IF(AND(AH$4>=$E8,AH$4<=$F8),IF($D8="Milestone","D",1),""))
A9: =WBS!A6 -> PF-05 | B9: =WBS!B6 -> Roles & RACI | C9: =WBS!E6 -> Dejan | D9: =WBS!D6 -> Formulation & Docs | E9: =WBS!L6 -> 46226 | F9: =WBS!M6 -> 46226 | G9: =IF($E9="","",IF(AND(G$4>=$E9,G$4<=$F9),IF($D9="Milestone","D",1),"")) -> 1 | H9: =IF($E9="","",IF(AND(H$4>=$E9,H$4<=$F9),IF($D9="Milestone","D",1),"")) | I9: =IF($E9="","",IF(AND(I$4>=$E9,I$4<=$F9),IF($D9="Milestone","D",1),"")) | J9: =IF($E9="","",IF(AND(J$4>=$E9,J$4<=$F9),IF($D9="Milestone","D",1),"")) | K9: =IF($E9="","",IF(AND(K$4>=$E9,K$4<=$F9),IF($D9="Milestone","D",1),"")) | L9: =IF($E9="","",IF(AND(L$4>=$E9,L$4<=$F9),IF($D9="Milestone","D",1),"")) | M9: =IF($E9="","",IF(AND(M$4>=$E9,M$4<=$F9),IF($D9="Milestone","D",1),"")) | N9: =IF($E9="","",IF(AND(N$4>=$E9,N$4<=$F9),IF($D9="Milestone","D",1),"")) | ... AH9: =IF($E9="","",IF(AND(AH$4>=$E9,AH$4<=$F9),IF($D9="Milestone","D",1),""))
A10: =WBS!A7 -> PF-06 | B10: =WBS!B7 -> EoM - 1-DoF pendulum | C10: =WBS!E7 -> Dejan | D10: =WBS!D7 -> Formulation & Docs | E10: =WBS!L7 -> 46227 | F10: =WBS!M7 -> 46228 | G10: =IF($E10="","",IF(AND(G$4>=$E10,G$4<=$F10),IF($D10="Milestone","D",1),"")) | H10: =IF($E10="","",IF(AND(H$4>=$E10,H$4<=$F10),IF($D10="Milestone","D",1),"")) -> 1 | I10: =IF($E10="","",IF(AND(I$4>=$E10,I$4<=$F10),IF($D10="Milestone","D",1),"")) -> 1 | J10: =IF($E10="","",IF(AND(J$4>=$E10,J$4<=$F10),IF($D10="Milestone","D",1),"")) | K10: =IF($E10="","",IF(AND(K$4>=$E10,K$4<=$F10),IF($D10="Milestone","D",1),"")) | L10: =IF($E10="","",IF(AND(L$4>=$E10,L$4<=$F10),IF($D10="Milestone","D",1),"")) | M10: =IF($E10="","",IF(AND(M$4>=$E10,M$4<=$F10),IF($D10="Milestone","D",1),"")) | N10: =IF($E10="","",IF(AND(N$4>=$E10,N$4<=$F10),IF($D10="Milestone","D",1),"")) | ... AH10: =IF($E10="","",IF(AND(AH$4>=$E10,AH$4<=$F10),IF($D10="Milestone","D",1),""))
A11: =WBS!A8 -> PF-07 | B11: =WBS!B8 -> EoM - 3D cube | C11: =WBS!E8 -> Dejan | D11: =WBS!D8 -> Formulation & Docs | E11: =WBS!L8 -> 46230 | F11: =WBS!M8 -> 46231 | G11: =IF($E11="","",IF(AND(G$4>=$E11,G$4<=$F11),IF($D11="Milestone","D",1),"")) | H11: =IF($E11="","",IF(AND(H$4>=$E11,H$4<=$F11),IF($D11="Milestone","D",1),"")) | I11: =IF($E11="","",IF(AND(I$4>=$E11,I$4<=$F11),IF($D11="Milestone","D",1),"")) | J11: =IF($E11="","",IF(AND(J$4>=$E11,J$4<=$F11),IF($D11="Milestone","D",1),"")) | K11: =IF($E11="","",IF(AND(K$4>=$E11,K$4<=$F11),IF($D11="Milestone","D",1),"")) -> 1 | L11: =IF($E11="","",IF(AND(L$4>=$E11,L$4<=$F11),IF($D11="Milestone","D",1),"")) -> 1 | M11: =IF($E11="","",IF(AND(M$4>=$E11,M$4<=$F11),IF($D11="Milestone","D",1),"")) | N11: =IF($E11="","",IF(AND(N$4>=$E11,N$4<=$F11),IF($D11="Milestone","D",1),"")) | ... AH11: =IF($E11="","",IF(AND(AH$4>=$E11,AH$4<=$F11),IF($D11="Milestone","D",1),""))
A12: =WBS!A9 -> PF-08 | B12: =WBS!B9 -> Linearisation & controllability | C12: =WBS!E9 -> Dejan | D12: =WBS!D9 -> Formulation & Docs | E12: =WBS!L9 -> 46232 | F12: =WBS!M9 -> 46232 | G12: =IF($E12="","",IF(AND(G$4>=$E12,G$4<=$F12),IF($D12="Milestone","D",1),"")) | H12: =IF($E12="","",IF(AND(H$4>=$E12,H$4<=$F12),IF($D12="Milestone","D",1),"")) | I12: =IF($E12="","",IF(AND(I$4>=$E12,I$4<=$F12),IF($D12="Milestone","D",1),"")) | J12: =IF($E12="","",IF(AND(J$4>=$E12,J$4<=$F12),IF($D12="Milestone","D",1),"")) | K12: =IF($E12="","",IF(AND(K$4>=$E12,K$4<=$F12),IF($D12="Milestone","D",1),"")) | L12: =IF($E12="","",IF(AND(L$4>=$E12,L$4<=$F12),IF($D12="Milestone","D",1),"")) | M12: =IF($E12="","",IF(AND(M$4>=$E12,M$4<=$F12),IF($D12="Milestone","D",1),"")) -> 1 | N12: =IF($E12="","",IF(AND(N$4>=$E12,N$4<=$F12),IF($D12="Milestone","D",1),"")) | ... AH12: =IF($E12="","",IF(AND(AH$4>=$E12,AH$4<=$F12),IF($D12="Milestone","D",1),""))
A13: =WBS!A10 -> PF-09 | B13: =WBS!B10 -> Mass / inertia / CoM budget | C13: =WBS!E10 -> Dejan | D13: =WBS!D10 -> Formulation & Docs | E13: =WBS!L10 -> 46228 | F13: =WBS!M10 -> 46228 | G13: =IF($E13="","",IF(AND(G$4>=$E13,G$4<=$F13),IF($D13="Milestone","D",1),"")) | H13: =IF($E13="","",IF(AND(H$4>=$E13,H$4<=$F13),IF($D13="Milestone","D",1),"")) | I13: =IF($E13="","",IF(AND(I$4>=$E13,I$4<=$F13),IF($D13="Milestone","D",1),"")) -> 1 | J13: =IF($E13="","",IF(AND(J$4>=$E13,J$4<=$F13),IF($D13="Milestone","D",1),"")) | K13: =IF($E13="","",IF(AND(K$4>=$E13,K$4<=$F13),IF($D13="Milestone","D",1),"")) | L13: =IF($E13="","",IF(AND(L$4>=$E13,L$4<=$F13),IF($D13="Milestone","D",1),"")) | M13: =IF($E13="","",IF(AND(M$4>=$E13,M$4<=$F13),IF($D13="Milestone","D",1),"")) | N13: =IF($E13="","",IF(AND(N$4>=$E13,N$4<=$F13),IF($D13="Milestone","D",1),"")) | ... AH13: =IF($E13="","",IF(AND(AH$4>=$E13,AH$4<=$F13),IF($D13="Milestone","D",1),""))
A14: =WBS!A11 -> PF-10 | B14: =WBS!B11 -> Jump-up analysis | C14: =WBS!E11 -> Dejan | D14: =WBS!D11 -> Formulation & Docs | E14: =WBS!L11 -> 46233 | F14: =WBS!M11 -> 46233 | G14: =IF($E14="","",IF(AND(G$4>=$E14,G$4<=$F14),IF($D14="Milestone","D",1),"")) | H14: =IF($E14="","",IF(AND(H$4>=$E14,H$4<=$F14),IF($D14="Milestone","D",1),"")) | I14: =IF($E14="","",IF(AND(I$4>=$E14,I$4<=$F14),IF($D14="Milestone","D",1),"")) | J14: =IF($E14="","",IF(AND(J$4>=$E14,J$4<=$F14),IF($D14="Milestone","D",1),"")) | K14: =IF($E14="","",IF(AND(K$4>=$E14,K$4<=$F14),IF($D14="Milestone","D",1),"")) | L14: =IF($E14="","",IF(AND(L$4>=$E14,L$4<=$F14),IF($D14="Milestone","D",1),"")) | M14: =IF($E14="","",IF(AND(M$4>=$E14,M$4<=$F14),IF($D14="Milestone","D",1),"")) | N14: =IF($E14="","",IF(AND(N$4>=$E14,N$4<=$F14),IF($D14="Milestone","D",1),"")) -> 1 | ... AH14: =IF($E14="","",IF(AND(AH$4>=$E14,AH$4<=$F14),IF($D14="Milestone","D",1),""))
A15: =WBS!A12 -> PF-11a | B15: =WBS!B12 -> TDD - draft body | C15: =WBS!E12 -> ALL | D15: =WBS!D12 -> Formulation & Docs | E15: =WBS!L12 -> 46228 | F15: =WBS!M12 -> 46229 | G15: =IF($E15="","",IF(AND(G$4>=$E15,G$4<=$F15),IF($D15="Milestone","D",1),"")) | H15: =IF($E15="","",IF(AND(H$4>=$E15,H$4<=$F15),IF($D15="Milestone","D",1),"")) | I15: =IF($E15="","",IF(AND(I$4>=$E15,I$4<=$F15),IF($D15="Milestone","D",1),"")) -> 1 | J15: =IF($E15="","",IF(AND(J$4>=$E15,J$4<=$F15),IF($D15="Milestone","D",1),"")) -> 1 | K15: =IF($E15="","",IF(AND(K$4>=$E15,K$4<=$F15),IF($D15="Milestone","D",1),"")) | L15: =IF($E15="","",IF(AND(L$4>=$E15,L$4<=$F15),IF($D15="Milestone","D",1),"")) | M15: =IF($E15="","",IF(AND(M$4>=$E15,M$4<=$F15),IF($D15="Milestone","D",1),"")) | N15: =IF($E15="","",IF(AND(N$4>=$E15,N$4<=$F15),IF($D15="Milestone","D",1),"")) | ... AH15: =IF($E15="","",IF(AND(AH$4>=$E15,AH$4<=$F15),IF($D15="Milestone","D",1),""))
A16: =WBS!A13 -> PF-11b | B16: =WBS!B13 -> TDD - deepen + S1 data | C16: =WBS!E13 -> ALL | D16: =WBS!D13 -> Formulation & Docs | E16: =WBS!L13 -> 46235 | F16: =WBS!M13 -> 46236 | G16: =IF($E16="","",IF(AND(G$4>=$E16,G$4<=$F16),IF($D16="Milestone","D",1),"")) | H16: =IF($E16="","",IF(AND(H$4>=$E16,H$4<=$F16),IF($D16="Milestone","D",1),"")) | I16: =IF($E16="","",IF(AND(I$4>=$E16,I$4<=$F16),IF($D16="Milestone","D",1),"")) | J16: =IF($E16="","",IF(AND(J$4>=$E16,J$4<=$F16),IF($D16="Milestone","D",1),"")) | K16: =IF($E16="","",IF(AND(K$4>=$E16,K$4<=$F16),IF($D16="Milestone","D",1),"")) | L16: =IF($E16="","",IF(AND(L$4>=$E16,L$4<=$F16),IF($D16="Milestone","D",1),"")) | M16: =IF($E16="","",IF(AND(M$4>=$E16,M$4<=$F16),IF($D16="Milestone","D",1),"")) | N16: =IF($E16="","",IF(AND(N$4>=$E16,N$4<=$F16),IF($D16="Milestone","D",1),"")) | ... AH16: =IF($E16="","",IF(AND(AH$4>=$E16,AH$4<=$F16),IF($D16="Milestone","D",1),""))
... A98: =WBS!A95 -> M8 | B98: =WBS!B95 -> GATE: Final delivery | C98: =WBS!E95 -> All | D98: =WBS!D95 -> Milestone | E98: =WBS!L95 -> 46253 | F98: =WBS!M95 -> 46253 | G98: =IF($E98="","",IF(AND(G$4>=$E98,G$4<=$F98),IF($D98="Milestone","D",1),"")) | H98: =IF($E98="","",IF(AND(H$4>=$E98,H$4<=$F98),IF($D98="Milestone","D",1),"")) | I98: =IF($E98="","",IF(AND(I$4>=$E98,I$4<=$F98),IF($D98="Milestone","D",1),"")) | J98: =IF($E98="","",IF(AND(J$4>=$E98,J$4<=$F98),IF($D98="Milestone","D",1),"")) | K98: =IF($E98="","",IF(AND(K$4>=$E98,K$4<=$F98),IF($D98="Milestone","D",1),"")) | L98: =IF($E98="","",IF(AND(L$4>=$E98,L$4<=$F98),IF($D98="Milestone","D",1),"")) | M98: =IF($E98="","",IF(AND(M$4>=$E98,M$4<=$F98),IF($D98="Milestone","D",1),"")) | N98: =IF($E98="","",IF(AND(N$4>=$E98,N$4<=$F98),IF($D98="Milestone","D",1),"")) | ... AH98: =IF($E98="","",IF(AND(AH$4>=$E98,AH$4<=$F98),IF($D98="Milestone","D",1),"")) -> D
A101: LEGEND
B102: Formulation & Docs
B103: Control & Software
B104: CAD Design
B105: Manufacturing & Circuits
A106: D | B106: Milestone gate
A108: Grey columns are weekends. NOTE: this plan treats them as working days.

Sheet Gantt Chart
A1: Classic stacked-bar Gantt (same data, chart form)
A2: Series 1 is the invisible offset (Start), series 2 is the bar (Span). Right-click a bar > Format Data Series to recolour by workstream.
